Workbook

Sheet Sommaire
A1: CARTOGRAPHIE FISCALE IMMOBILIÈRE 2026
A2: Référentiel pour MVP simulateur fiscal - À valider par expert-comptable avant intégration
A4: FEUILLE | B4: CONTENU | C4: RÉGIME(S) | D4: USAGE MVP
A5: 01_Paramètres_2026 | B5: Tous les barèmes, seuils, taux LF 2026 + LFSS 2026 | C5: Référentiel global | D5: Source unique de vérité - à mettre à jour chaque année
A6: 02_Inputs_simulation | B6: Variables d'entrée utilisateur + caractéristiques bien | C6: Tous | D6: Cellules jaunes à brancher sur les champs UI
A7: 03_Micro_foncier | B7: Location nue - régime forfaitaire 30% | C7: Particulier nom propre | D7: Cas le plus simple - bon point d'entrée pédagogique
A8: 04_Réel_foncier | B8: Location nue - régime réel + déficit foncier | C8: Particulier nom propre | D8: Inclut mécanisme déficit foncier (10 700€/an)
A9: 05_Micro_BIC_LMNP | B9: Location meublée - micro-BIC | C9: Particulier nom propre | D9: Abattement 50% (LD) ou 30% (tourisme NC)
A10: 06_Réel_BIC_LMNP | B10: Location meublée - régime réel + amortissement | C10: Particulier nom propre | D10: Inclut amortissement bâti/mobilier + plus-value LF 2025
A11: 07_LMP | B11: Loueur Meublé Professionnel | C11: Particulier nom propre | D11: Bascule auto si > 23k€ ET > autres revenus
A12: 08_SCI_IR | B12: SCI translucide à l'IR | C12: Société civile | D12: Régime par défaut - imposition chez associés
A13: 09_SCI_IS | B13: SCI à l'IS | C13: Société civile | D13: Option irrévocable - amortissement + IS 15/25%
A14: 10_Pinel_Denormandie | B14: Réductions d'impôt (dispositifs en extinction) | C14: Particulier nom propre | D14: ATTENTION : Pinel arrêté 31/12/2024
A15: 11_Plus_values | B15: Plus-values immobilières par régime | C15: Tous | D15: Comparaison fiscalité de sortie
... A17: 13_Hypothèses_calcul | B17: Conventions, durées d'amortissement, sources légales | C17: Documentation | D17: Pour audit expert-comptable
A19: ⚠️ AVERTISSEMENTS
A20: 1. | B20: Tous les calculs reposent sur les barèmes 2026 (LF n° 2026-103 du 19/02/2026 + LFSS 2026)
A21: 2. | B21: Les optimisations fiscales personnalisées (démembrement, holding, donation parts) ne sont pas couvertes
A22: 3. | B22: Le simulateur doit afficher un disclaimer : 'outil d'aide à la décision, ne remplace pas un conseil personnalisé'
A23: 4. | B23: Faire valider chaque feuille par un expert-comptable ou avocat fiscaliste avant mise en production
A24: 5. | B24: Le statut 'Bailleur Privé' (LF 2026) qui remplace partiellement Pinel n'est pas modélisé en V1 - décrets en attente

Sheet 01_Paramètres_2026
A1: PARAMÈTRES FISCAUX 2026 (revenus 2025 déclarés en 2026)
A3: BARÈME IMPÔT SUR LE REVENU 2026 (par part de quotient familial)
A4: Tranche | B4: Borne basse (€) | C4: Borne haute (€) | D4: Taux | E4: Source
A5: Tranche 1 | B5: 0 | C5: 11600 | D5: 0 | E5: LF 2026 art. 4 - Tranche revalorisée +0,9%
A6: Tranche 2 | B6: 11600 | C6: 29579 | D6: 0.11 | E6: LF 2026 art. 4
A7: Tranche 3 | B7: 29579 | C7: 84577 | D7: 0.3 | E7: LF 2026 art. 4
A8: Tranche 4 | B8: 84577 | C8: 181917 | D8: 0.41 | E8: LF 2026 art. 4
A9: Tranche 5 | B9: 181917 | C9: 9999999 | D9: 0.45 | E9: LF 2026 art. 4
A11: DÉCOTE 2026
A12: Paramètre | B12: Valeur | E12: Source
A13: Plafond impôt brut célibataire | B13: 1982 | E13: LF 2026
A14: Plafond impôt brut couple | B14: 3277 | E14: LF 2026
A15: Forfait décote célibataire | B15: 897 | E15: LF 2026
A16: Forfait décote couple | B16: 1483 | E16: LF 2026
A17: Taux décote | B17: 0.4525 | E17: Décote = forfait - 45,25% × IR brut
A19: PRÉLÈVEMENTS SOCIAUX 2026 (LFSS 2026 - hausse CSG 1,4 pt)
A20: Type de revenu | B20: Taux global PS | C20: CSG totale | D20: CSG déductible | E20: Source
A21: Revenus fonciers (location nue) | B21: 0.172 | C21: 0.092 | D21: 0.068 | E21: EXCLU de la hausse - LFSS 2026 art. 12
A22: BIC LMNP non professionnel | B22: 0.186 | C22: 0.106 | D22: 0.068 | E22: LFSS 2026 art. 12 (rétroactif rev. 2025)
A23: Plus-value immobilière | B23: 0.172 | C23: 0.092 | D23: 0 | E23: EXCLU - non déductible
A24: Dividendes (SCI IS distribués) | B24: 0.186 | C24: 0.106 | D24: 0.068 | E24: LFSS 2026 art. 12
A25: LMP (cotisations sociales TNS) | B25: 0.3 | C25: 0 | D25: 0 | E25: Cotisations indép. ~30-45% selon CA
A28: SEUILS RÉGIMES MICRO 2026
A29: Régime | B29: Plafond CA (€) | C29: Abattement | D29: Plancher abat. | E29: Source
A30: Micro-foncier (location nue) | B30: 15000 | C30: 0.3 | D30: 0 | E30: Art. 32 CGI
A31: Micro-BIC location meublée LD | B31: 77700 | C31: 0.5 | D31: 305 | E31: Art. 50-0 CGI
A32: Micro-BIC meublé tourisme classé | B32: 77700 | C32: 0.5 | D32: 305 | E32: Loi Le Meur 2024 - reval. triennale
A33: Micro-BIC meublé tourisme NON classé | B33: 15000 | C33: 0.3 | D33: 305 | E33: Loi Le Meur 19/11/2024
A34: Seuil bascule LMP/LMNP (recettes) | B34: 23000 | C34: 0 | D34: 0 | E34: Art. 155 IV CGI - cumulatif foyer
A37: IMPÔT SUR LES SOCIÉTÉS 2026
A38: Tranche | B38: Borne basse (€) | C38: Borne haute (€) | D38: Taux | E38: Source / Conditions
A39: Taux réduit PME | B39: 0 | C39: 42500 | D39: 0.15 | E39: CA < 10M€, capital libéré, détention ≥75% personnes physiques
A40: Taux normal | B40: 42500 | C40: 9999999 | D40: 0.25 | E40: Art. 219 I CGI
A43: PLUS-VALUES IMMOBILIÈRES (régime particulier - art. 150 U CGI)
A44: Paramètre | B44: Valeur | E44: Notes
A45: Taux IR plus-value | B45: 0.19 | E45: Forfaitaire art. 200 B CGI
A46: Taux PS plus-value | B46: 0.172 | E46: Pas de hausse LFSS 2026
A47: Abattement IR par an de détention (6e à 21e année) | B47: 0.06 | E47: Soit 6% × 16 ans = 96%
A48: Abattement IR 22e année | B48: 0.04 | E48: Total 100% à 22 ans
A49: Abattement PS par an (6e à 21e année) | B49: 0.0165 | E49: 1,65% × 16 ans = 26,4%
...

Sheet 02_Inputs_simulation
A1: VARIABLES D'ENTRÉE - SIMULATION UTILISATEUR
A2: Cellules JAUNES = inputs utilisateur. Toutes les feuilles régimes pointent vers ces cellules.
A4: § SITUATION PERSONNELLE
A5: TMI estimée du foyer | B5: 0.3 | C5: % | D5: Calculée depuis revenus déclarés - inputs UI
A6: Nombre de parts fiscales | B6: 2 | C6: parts | D6: Quotient familial
A7: Revenu net imposable hors immo | B7: 60000 | C7: €/an | D7: Hors revenus locatifs
A9: § CARACTÉRISTIQUES DU BIEN
A10: Prix d'acquisition (FAI) | B10: 250000 | C10: € | D10: Frais d'agence inclus
A11: Frais de notaire | B11: 17500 | C11: € | D11: ≈ 7% ancien, 2-3% neuf
A12: Travaux initiaux | B12: 15000 | C12: € | D12: Travaux à l'achat
A13: Mobilier (si meublé) | B13: 8000 | C13: € | D13: Pour LMNP uniquement
A14: Quote-part terrain | B14: 0.15 | C14: % | D14: Non amortissable
A16: § FINANCEMENT
A17: Apport personnel | B17: 30000 | C17: €
A18: Montant emprunté | B18: =B10+B11+B12-B17 -> 252500 | C18: € | D18: (prix + frais + travaux - apport)
A19: Taux d'intérêt | B19: 0.04 | C19: % | D19: Taux nominal hors assurance
A20: Durée emprunt | B20: 20 | C20: années
A21: Taux assurance emprunt | B21: 0.0036 | C21: % | D21: ≈ 0,30 à 0,40% du capital initial
A23: § EXPLOITATION ANNUELLE
A24: Loyer mensuel HC | B24: 1100 | C24: €/mois | D24: Hors charges
A25: Loyer annuel brut | B25: =B24*12 -> 13200 | C25: €/an | D25: (mensuel × 12)
A26: Vacance locative estimée | B26: 0.04 | C26: % | D26: ≈ 1 mois sur 24
A27: Charges non récupérables | B27: 600 | C27: €/an | D27: Copropriété part propriétaire
A28: Taxe foncière | B28: 1400 | C28: €/an
A29: Assurance PNO | B29: 180 | C29: €/an | D29: Propriétaire non occupant
A30: Frais de gestion | B30: 0 | C30: €/an | D30: Si délégation à agence (~7-8% loyers)
A31: Travaux d'entretien (provision) | B31: 600 | C31: €/an | D31: ≈ 5% du loyer brut
A32: Comptable (LMNP réel / SCI) | B32: 600 | C32: €/an | D32: ≈ 500-1000€/an
A34: § HORIZON DE DÉTENTION
A35: Durée de détention envisagée | B35: 20 | C35: années | D35: Pour calcul plus-value
A36: Valorisation annuelle estimée | B36: 0.02 | C36: % | D36: Hypothèse appréciation bien

Sheet 03_Micro_foncier
A1: RÉGIME MICRO-FONCIER (location nue)
A2: Conditions: revenus fonciers bruts ≤ 15 000 €/an + bien NON soumis à régime particulier (Borloo, Pinel, monuments historiques)
A4: 1. RECETTES & ASSIETTE IMPOSABLE
A5: Loyer brut annuel | B5: =02_Inputs_simulation!$B$25 -> 13200 | D5: Cf. 02_Inputs B25
A6: Vacance locative | B6: =-02_Inputs_simulation!$B$25*02_Inputs_simulation!$B$26 -> -528 | D6: (-loyer × taux vacance)
A7: Recettes nettes | B7: =B5+B6 -> 12672 | D7: Base imposable BRUTE
A8: Vérif. seuil 15 000 € | B8: =IF(B7<=01_Paramètres_2026!$B$30,"✓ Éligible micro-foncier","✗ HORS PLAFOND - bascule auto régime réel") -> ✓ Éligible micro-foncier
A9: Abattement forfaitaire (30%) | B9: =-B7*01_Paramètres_2026!$C$30 -> -3801.6 | D9: Réputé couvrir TOUTES les charges
A10: Revenu foncier imposable | B10: =B7+B9 -> 8870.4 | D10: (base IR + base PS)
A12: 2. IMPÔT SUR LE REVENU
A13: TMI applicable | B13: =02_Inputs_simulation!$B$5 -> 0.3
A14: IR sur revenu foncier | B14: =B10*B13 -> 2661.12 | D14: Approximation TMI - calcul exact via barème complet sur 12_Comparateur
A16: 3. PRÉLÈVEMENTS SOCIAUX
A17: Taux PS (location nue) | B17: =01_Paramètres_2026!$B$21 -> 0.172 | D17: EXCLU hausse LFSS 2026
A18: Montant PS | B18: =B10*B17 -> 1525.7088
A20: 4. CHARGE FISCALE TOTALE
A21: IR + PS | B21: =B14+B18 -> 4186.8288
A22: Taux d'imposition effectif | B22: =B21/B7 -> 0.3304
A24: 5. CASH-FLOW NET ANNUEL
A25: Recettes nettes | B25: =B7 -> 12672
A26: - Charges réelles (NON déductibles ici) | B26: =-(02_Inputs_simulation!$B$27+02_Inputs_simulation!$B$28+02_Inputs_simulation!$B$29+02_Inputs_simulation!$B$30+02_Inputs_simulation!$B$31) -> -2780 | D26: Subies mais non déduites fiscalement
A27: - Mensualités emprunt (capital + intérêts) | B27: =-(IF(02_Inputs_simulation!$B$18>0,-PMT((02_Inputs_simulation!$B$19+02_Inputs_simulation!$B$21)/12,02_Inputs_simulation!$B$20*12,02_Inputs_simulation!$B$18)*12,0)) -> -18941.054 | D27: PMT calcule la mensualité d'emprunt assurance incluse
A28: - IR + PS | B28: =-B21 -> -4186.8288
A29: (Cash-flow net annuel) | B29: =B25+B26+B27+B28 -> -13235.883
A31: 6. AVANTAGES / INCONVÉNIENTS
A32: ✓ Simplicité maximale (1 case sur déclaration 2042 - case 4BE)
A33: ✓ Pas d'obligation comptable
A34: ✓ Pas de gestion de déficit foncier
A35: ✗ Aucune charge déductible (tout est forfaitaire à 30%)
A36: ✗ Inadapté si charges réelles > 30% des loyers (typiquement avec emprunt en cours)
A37: ✗ Plafonné à 15 000 € de recettes annuelles
A38: ✗ Pas d'amortissement possible
A39: → Pertinent pour : bien sans emprunt, charges très faibles, simplicité prioritaire

Sheet 04_Réel_foncier
A1: RÉGIME RÉEL FONCIER (location nue)
A2: Sur option ou obligatoire si recettes > 15 000 €/an. Toutes charges réelles déductibles + déficit foncier imputable.
A4: 1. RECETTES
A5: Loyer brut annuel | B5: =02_Inputs_simulation!$B$25 -> 13200
A6: Vacance | B6: =-02_Inputs_simulation!$B$25*02_Inputs_simulation!$B$26 -> -528
A7: Recettes nettes | B7: =B5+B6 -> 12672
A9: 2. CHARGES DÉDUCTIBLES (art. 31 CGI)
A10: Charges de copropriété non récupérables | B10: =-02_Inputs_simulation!$B$27 -> -600
A11: Taxe foncière | B11: =-02_Inputs_simulation!$B$28 -> -1400
A12: Assurance PNO | B12: =-02_Inputs_simulation!$B$29 -> -180
A13: Frais de gestion | B13: =-02_Inputs_simulation!$B$30 -> 0
A14: Travaux d'entretien et réparation | B14: =-02_Inputs_simulation!$B$31 -> -600 | D14: Travaux d'AMÉLIORATION = OUI ; CONSTRUCTION/AGRANDISSEMENT = NON
A15: Intérêts d'emprunt + assurance | B15: =-(02_Inputs_simulation!$B$18*02_Inputs_simulation!$B$19+02_Inputs_simulation!$B$18*02_Inputs_simulation!$B$21) -> -11009 | D15: Approximation 1ère année - en réalité dégressif
A16: Forfait frais de gestion (20 €/local) | B16: -20 | D16: Forfaitaire art. 31-I-1°-c
A17: Total charges | B17: =SUM(B10:B16) -> -13809
A19: 3. RÉSULTAT FONCIER
A20: Résultat foncier brut | B20: =B7+B17 -> -1137 | D20: Si négatif → déficit foncier
A21: Dont intérêts d'emprunt (à isoler) | B21: =-B15 -> 11009 | D21: Les intérêts ne s'imputent PAS sur le revenu global
A22: Déficit hors intérêts | B22: =IF(B20<0,MIN(0,B20-B21),0) -> -12146 | D22: Imputable sur revenu global jusqu'à 10 700 €
A23: Plafond imputation revenu global | B23: =-01_Paramètres_2026!$B$70 -> -10700
A24: Déficit imputé sur revenu global | B24: =MAX(B22,B23) -> -10700
A25: Déficit reportable (10 ans) | B25: =MIN(0,B22-B24) -> -1446 | D25: Reportable sur revenus fonciers UNIQUEMENT pdt 10 ans
A26: Revenu foncier imposable (si positif) | B26: =MAX(0,B20) -> 0
A28: 4. IMPACT FISCAL ANNÉE COURANTE
A29: TMI | B29: =02_Inputs_simulation!$B$5 -> 0.3
A30: IR sur revenu foncier (si positif) | B30: =B26*B29 -> 0
A31: Économie IR via déficit (si négatif) | B31: =B24*B29 -> -3210 | D31: Imputation sur revenu global
A32: PS sur revenu foncier | B32: =B26*01_Paramètres_2026!$B$21 -> 0
A33: PS économisés (déficit ne génère PAS d'éco PS) | B33: 0 | D33: PS uniquement sur revenus positifs
A35: 5. CHARGE FISCALE NETTE
A36: Total IR + PS (ou économie si déficit) | B36: =B30+B31+B32 -> -3210
A37: Taux d'imposition effectif sur loyers | B37: =IF(B7>0,B36/B7,0) -> -0.25331439
A39: 6. POINTS-CLÉS DU RÉGIME
A40: ✓ Toutes charges réelles déductibles (intérêts, travaux, taxe foncière, etc.)
A41: ✓ Mécanisme du déficit foncier puissant : 10 700 €/an sur revenu global, doublé en cas travaux énergétiques (jusqu'au 31/12/2025)
A42: ✓ Déficit excédentaire reportable 10 ans sur revenus fonciers
A43: ✓ Engagement: maintenir location 3 ans après imputation du déficit
A44: ✗ Comptabilité plus lourde - déclaration 2044
A45: ✗ Choix engageant : option pour 3 ans minimum
A46: ✗ Travaux d'agrandissement/construction NON déductibles
...

Sheet 05_Micro_BIC_LMNP
A1: MICRO-BIC LMNP (location meublée)
A2: Régime forfaitaire BIC - abattement 50% en location meublée longue durée
A4: 1. RECETTES
A5: Loyer brut annuel meublé | B5: =02_Inputs_simulation!$B$25 -> 13200 | D5: ATTENTION : si meublé, le loyer doit déjà être 'meublé' (10-30% > nu)
A6: Vacance | B6: =-02_Inputs_simulation!$B$25*02_Inputs_simulation!$B$26 -> -528
A7: Recettes nettes | B7: =B5+B6 -> 12672
A8: Vérif. seuil 77 700 € | B8: =IF(B7<=01_Paramètres_2026!$B$31,"✓ Éligible micro-BIC","✗ HORS PLAFOND") -> ✓ Éligible micro-BIC
A9: Vérif. seuil LMP 23 000 € | B9: =IF(B7<01_Paramètres_2026!$B$34,"✓ Reste LMNP","⚠ Vérifier basculement LMP") -> ✓ Reste LMNP | D9: LMP si recettes > 23k€ ET > autres revenus pro foyer
A11: 2. ASSIETTE IMPOSABLE
A12: Abattement forfaitaire (50%) | B12: =-B7*01_Paramètres_2026!$C$31 -> -6336 | D12: Réputé couvrir TOUTES charges + amortissements
A13: Bénéfice imposable BIC | B13: =B7+B12 -> 6336
A15: 3. IMPÔT SUR LE REVENU
A16: TMI | B16: =02_Inputs_simulation!$B$5 -> 0.3
A17: IR sur bénéfice BIC | B17: =B13*B16 -> 1900.8
A19: 4. PRÉLÈVEMENTS SOCIAUX
A20: Taux PS (LMNP - hausse LFSS 2026) | B20: =01_Paramètres_2026!$B$22 -> 0.186 | D20: 18,6% depuis LFSS 2026 - rétroactif rev. 2025
A21: Montant PS | B21: =B13*B20 -> 1178.496
A23: 5. CHARGE FISCALE TOTALE
A24: IR + PS | B24: =B17+B21 -> 3079.296
A25: Taux d'imposition effectif | B25: =B24/B7 -> 0.243
A27: 6. CAS PARTICULIER : MEUBLÉ DE TOURISME NON CLASSÉ
A28: Abattement (au lieu de 50%) | B28: 0.3 | D28: Loi Le Meur 19/11/2024
A29: Plafond (au lieu de 77 700) | B29: 15000
A30: Bénéfice imposable (tourisme NC) | B30: =B7*(1-B28) -> 8870.4
A31: IR + PS (tourisme NC) | B31: =B30*(B16+01_Paramètres_2026!$B$22) -> 4311.0144
A33: 7. POINTS-CLÉS
A34: ✓ Simplicité maximale (case 5ND déclaration 2042-C-PRO)
A35: ✓ Abattement 50% souvent supérieur aux charges réelles SANS emprunt
A36: ✓ Pas d'obligation comptable (mais création EI + SIRET via INPI obligatoire)
A37: ✗ Inadapté SI emprunt en cours (réel + amortissement bien plus avantageux)
A38: ✗ Réforme Loi Le Meur (11/2024) : meublés tourisme NON classés rabaissés à 15k€/30%
A39: ✗ Les amortissements pratiqués au régime réel sont réintégrés dans la PV à la revente (LF 2025)
A40: → Pertinent pour : petits revenus locatifs SANS emprunt, simplicité prioritaire

Sheet 06_Réel_BIC_LMNP
A1: RÉGIME RÉEL LMNP (location meublée)
A2: Sur option ou obligatoire si > 77 700 €. Amortissement bâti+mobilier = neutralisation fiscale puissante.
A4: 1. RECETTES
A5: Loyer brut annuel | B5: =02_Inputs_simulation!$B$25 -> 13200
A6: Vacance | B6: =-02_Inputs_simulation!$B$25*02_Inputs_simulation!$B$26 -> -528
A7: Recettes nettes | B7: =B5+B6 -> 12672
A9: 2. CHARGES DÉDUCTIBLES
A10: Charges copropriété | B10: =-02_Inputs_simulation!$B$27 -> -600
A11: Taxe foncière | B11: =-02_Inputs_simulation!$B$28 -> -1400
A12: Assurance PNO | B12: =-02_Inputs_simulation!$B$29 -> -180
A13: Frais de gestion | B13: =-02_Inputs_simulation!$B$30 -> 0
A14: Travaux d'entretien | B14: =-02_Inputs_simulation!$B$31 -> -600
A15: Honoraires comptable | B15: =-02_Inputs_simulation!$B$32 -> -600
A16: Intérêts emprunt + assurance | B16: =-(02_Inputs_simulation!$B$18*02_Inputs_simulation!$B$19+02_Inputs_simulation!$B$18*02_Inputs_simulation!$B$21) -> -11009
A17: CFE (Cotisation Foncière Entreprises) | B17: -300 | D17: Variable selon commune ~200-800€/an
A18: Total charges courantes | B18: =SUM(B10:B17) -> -14689
A20: 3. AMORTISSEMENTS
A21: Base amortissable totale | B21: =02_Inputs_simulation!$B$10+02_Inputs_simulation!$B$11+02_Inputs_simulation!$B$12 -> 282500 | D21: Prix + frais + travaux (intégrés à la base)
A22: Quote-part terrain (NON amortissable) | B22: =-B21*02_Inputs_simulation!$B$14 -> -42375
A23: Base amortissable bâti | B23: =B21+B22 -> 240125
A24: Gros œuvre (40% / 80 ans) | B24: =-B23*0.4/80 -> -1200.625
A25: Façade/étanchéité (10% / 30 ans) | B25: =-B23*0.1/30 -> -800.41667
A26: Installations techniques (20% / 25 ans) | B26: =-B23*0.2/25 -> -1921
A27: Agencements (15% / 15 ans) | B27: =-B23*0.15/15 -> -2401.25
A28: Autres (15%) | B28: =-B23*0.15/40 -> -900.46875 | D28: Moyenne pondérée résiduel
A29: Amortissement bâti annuel | B29: =SUM(B24:B28) -> -7223.7604
A30: Amortissement mobilier (sur 7 ans) | B30: =-02_Inputs_simulation!$B$13/7 -> -1142.8571
A31: Total amortissements annuels | B31: =B29+B30 -> -8366.6176
A33: 4. RÉSULTAT BIC
A34: Résultat AVANT amortissement | B34: =B7+B18 -> -2017
A35: Résultat APRÈS amortissement (théorique) | B35: =B34+B31 -> -10383.618 | D35: Souvent négatif → 0 € imposable
A36: Règle anti-déficit LMNP | B36: =IF(B35<0,B34,B35) -> -2017 | D36: Amortissement plafonné au résultat avant amort. - excédent reporté
A37: Amortissement utilisé année courante | B37: =IF(B35<0,-B34,-B31) -> 2017 | D37: Différence reportable indéfiniment
A38: Amortissement reportable | B38: =IF(B35<0,-B35,0) -> 10383.618 | D38: Cumul reportable sans limite (vs déficit foncier 10 ans)
A39: Bénéfice imposable BIC | B39: =MAX(0,B36) -> 0
A41: 5. IMPÔT
A42: TMI | B42: =02_Inputs_simulation!$B$5 -> 0.3
A43: IR sur bénéfice BIC | B43: =B39*B42 -> 0
A44: PS (18,6% LFSS 2026) | B44: =B39*01_Paramètres_2026!$B$22 -> 0
A45: Total IR + PS | B45: =B43+B44 -> 0
...

Sheet 07_LMP
A1: LMP - LOUEUR MEUBLÉ PROFESSIONNEL
A2: Bascule automatique si recettes > 23 000 € ET > autres revenus pro foyer (art. 155 IV CGI)
A4: 1. CONDITIONS D'ÉLIGIBILITÉ LMP
A5: Recettes annuelles meublé | B5: =02_Inputs_simulation!$B$25 -> 13200
A6: Autres revenus pro foyer (BIC/BNC/BA/salaires) | B6: '02_Inputs_simulation'!$B$7 | D6: (revenu hors immo - cf. inputs)
A7: Condition 1 : recettes > 23 000 € | B7: =IF(B5>01_Paramètres_2026!$B$34,"OUI","NON") -> NON
A8: Condition 2 : recettes > autres revenus | B8: =IF(B5>B6,"OUI","NON") -> NON
A9: STATUT FINAL | B9: =IF(AND(B7="OUI",B8="OUI"),"LMP","LMNP") -> LMNP
A11: 2. CALCUL FISCAL (similaire LMNP réel)
A12: Recettes nettes | B12: =02_Inputs_simulation!$B$25*(1-02_Inputs_simulation!$B$26) -> 12672
A13: Charges courantes (cf. 06_LMNP réel) | B13: =06_Réel_BIC_LMNP!B18 -> -14689
A14: Amortissements | B14: =06_Réel_BIC_LMNP!B31 -> -8366.6176
A15: Résultat avant amort | B15: =B12+B13 -> -2017
A16: Résultat après amort (théorique) | B16: =B15+B14 -> -10383.618
A17: Bénéfice imposable | B17: =MAX(0,IF(B16<0,B15,B16)) -> 0 | D17: Règle anti-déficit s'applique aussi en LMP
A19: 3. SPÉCIFICITÉS LMP - DIFFÉRENCES MAJEURES vs LMNP
A20: TMI | B20: =02_Inputs_simulation!$B$5 -> 0.3
A21: IR sur bénéfice | B21: =B17*B20 -> 0
A22: Cotisations sociales TNS (~30-45%) | B22: =-B17*0.3 -> 0 | D22: ATTENTION : assujettissement SSI (ex-RSI) à la place des PS 18,6%
A23: Pas de PS 18,6% en LMP | B23: 0
A24: Total prélèvements | B24: =B21-B22 -> 0
A26: 4. AVANTAGES LMP MAJEURS
A27: ✓ Déficit BIC imputable sur le revenu GLOBAL sans plafond (vs 10 700€ déficit foncier)
A28: ✓ Plus-value PROFESSIONNELLE : exonération TOTALE après 5 ans si recettes < 90k€/250k€
A29: ✓ Pas de réintégration des amortissements dans la plus-value (vs réforme LMNP LF 2025)
A30: ✓ Exonération IFI sur biens donnés en location meublée pro
A31: ✗ Cotisations sociales SSI lourdes (~30-45% du résultat) - parfois > PS 18,6% LMNP
A32: ✗ Affiliation obligatoire à la sécurité sociale des indépendants
A33: ✗ Comptabilité plus lourde, obligation BIC pro complète
A34: ⚠ Bascule LMP/LMNP est AUTOMATIQUE - vérifier seuils chaque année
A35: → Pertinent pour : gros patrimoine meublé, optimisation transmission, cash-flow significatif

Sheet 08_SCI_IR
A1: SCI À L'IMPÔT SUR LE REVENU (régime par défaut)
A2: Société transparente fiscalement - imposition chez les associés au prorata des parts
A4: 1. NATURE DU RÉGIME
A5: Une SCI n'a pas de fiscalité propre en IR - elle est translucide
A6: Chaque associé est imposé sur sa quote-part de bénéfice = comme s'il détenait le bien en direct
A7: Mais SOUS CONDITION : la SCI ne doit faire QUE de la location nue (pas de meublé sauf accessoire)
A8: Si meublé → bascule automatique à l'IS irrévocable
A9: Application du régime des revenus fonciers (cf. 03 micro-foncier ou 04 réel foncier)
A11: 2. CALCUL SIMPLIFIÉ (associé unique 100%)
A12: Loyer brut annuel SCI | B12: =02_Inputs_simulation!$B$25 -> 13200
A13: Vacance | B13: =-02_Inputs_simulation!$B$25*02_Inputs_simulation!$B$26 -> -528
A14: Charges courantes | B14: =-(02_Inputs_simulation!$B$27+02_Inputs_simulation!$B$28+02_Inputs_simulation!$B$29+02_Inputs_simulation!$B$30+02_Inputs_simulation!$B$31) -> -2780
A15: Intérêts emprunt | B15: =-(02_Inputs_simulation!$B$18*02_Inputs_simulation!$B$19+02_Inputs_simulation!$B$18*02_Inputs_simulation!$B$21) -> -11009
A16: Honoraires comptable SCI | B16: =-02_Inputs_simulation!$B$32 -> -600
A17: Résultat foncier SCI | B17: =SUM(B12:B16) -> -1717
A19: 3. RÉPARTITION ENTRE ASSOCIÉS
A20: Quote-part associé principal | B20: 1 | D20: 100% par défaut
A21: Revenu foncier imputé à l'associé | B21: =B17*B20 -> -1717
A23: 4. IMPOSITION ASSOCIÉ
A24: TMI associé | B24: =02_Inputs_simulation!$B$5 -> 0.3
A25: IR sur revenu foncier | B25: =MAX(0,B21)*B24 -> 0
A26: PS (17,2% maintenu) | B26: =MAX(0,B21)*01_Paramètres_2026!$B$21 -> 0
A27: Économie IR si déficit (limité 10 700€) | B27: =IF(B21<0,MAX(B21,-10700)*B24,0) -> -515.1
A28: Total IR + PS (ou éco) | B28: =B25+B26+B27 -> -515.1
A30: 5. CAS PARTICULIER : MULTI-ASSOCIÉS
A31: Si SCI familiale 4 associés à 25% chacun : chaque associé déclare 1/4 du résultat
A32: TMI APPLIQUÉE = celle de chaque associé individuellement (pas une TMI moyenne)
A33: INTÉRÊT : démembrer parts pour donation, transmission progressive aux enfants
A34: Démembrement : usufruitier paie l'IR sur les loyers, nu-propriétaire ne paie rien
A35: ATTENTION : un associé sans revenu paye quand même les PS (17,2%)
A38: 6. POINTS-CLÉS SCI IR
A39: ✓ Régime simple, transparent, identique à la détention en direct
A40: ✓ Idéal pour patrimoine familial : transmission, donation parts, démembrement
A41: ✓ Mécanisme du déficit foncier disponible (10 700 € sur revenu global)
A42: ✓ PS maintenus à 17,2% (vs 18,6% LMNP)
A43: ✓ Pas d'amortissement = plus-value à la revente classique (régime PV particuliers)
... A48: → Pertinent pour : patrimoine familial, transmission, location nue, durée détention longue (>15 ans)

Sheet 09_SCI_IS
A1: SCI À L'IMPÔT SUR LES SOCIÉTÉS (sur option)
A2: Option IRRÉVOCABLE après 5 ans (art. 239 CGI). Amortissement possible. IS 15%/25% au lieu de TMI.
A4: 1. RÉSULTAT FISCAL DE LA SCI
A5: Loyer brut annuel | B5: =02_Inputs_simulation!$B$25 -> 13200
A6: Vacance | B6: =-02_Inputs_simulation!$B$25*02_Inputs_simulation!$B$26 -> -528
A7: Charges courantes | B7: =-(02_Inputs_simulation!$B$27+02_Inputs_simulation!$B$28+02_Inputs_simulation!$B$29+02_Inputs_simulation!$B$30+02_Inputs_simulation!$B$31) -> -2780
A8: Intérêts emprunt | B8: =-(02_Inputs_simulation!$B$18*02_Inputs_simulation!$B$19+02_Inputs_simulation!$B$18*02_Inputs_simulation!$B$21) -> -11009
A9: Honoraires comptable + frais juridiques | B9: =-1500 -> -1500 | D9: Comptable obligatoire IS plus cher
A11: 2. AMORTISSEMENTS (avantage clé SCI IS)
A12: Base amortissable | B12: =02_Inputs_simulation!$B$10+02_Inputs_simulation!$B$11+02_Inputs_simulation!$B$12 -> 282500
A13: Quote-part terrain | B13: =-B12*02_Inputs_simulation!$B$14 -> -42375
A14: Base bâti | B14: =B12+B13 -> 240125
A15: Amort. gros œuvre (40%/80 ans) | B15: =-B14*0.4/80 -> -1200.625
A16: Amort. façade (10%/30 ans) | B16: =-B14*0.1/30 -> -800.41667
A17: Amort. installations (20%/25 ans) | B17: =-B14*0.2/25 -> -1921
A18: Amort. agencements (15%/15 ans) | B18: =-B14*0.15/15 -> -2401.25
A19: Amort. autres (15%/40 ans) | B19: =-B14*0.15/40 -> -900.46875
A20: Amortissement annuel total | B20: =SUM(B15:B19) -> -7223.7604
A22: 3. RÉSULTAT IMPOSABLE IS
A23: Résultat fiscal société | B23: =SUM(B5:B9)+B20 -> -9840.7604 | D23: Si négatif : déficit reportable indéfiniment (sur résultats SCI uniquement)
A24: Résultat imposable (si positif) | B24: =MAX(0,B23) -> 0
A26: 4. CALCUL DE L'IS
A27: Plafond IS taux réduit | B27: =01_Paramètres_2026!$C$39 -> 42500
A28: IS taux réduit 15% (jusqu'à 42 500€) | B28: =MIN(B24,B27)*01_Paramètres_2026!$D$39 -> 0 | D28: Sous condition : CA<10M€ et capital libéré
A29: IS taux normal 25% (au-delà) | B29: =MAX(0,B24-B27)*01_Paramètres_2026!$D$40 -> 0
A30: IS total à payer par la SCI | B30: =B28+B29 -> 0
A31: Résultat NET société (après IS) | B31: =B24-B30 -> 0
A33: 5. DISTRIBUTION DE DIVIDENDES (optionnelle)
A34: % distribué aux associés | B34: 0.5 | D34: 0% si capitalisation, 100% si distribution totale
A35: Dividendes bruts | B35: =B31*B34 -> 0
A36: PFU 12,8% IR | B36: =B35*0.128 -> 0 | D36: Ou option barème (TMI) si plus avantageux
A37: PS 18,6% sur dividendes (LFSS 2026) | B37: =B35*01_Paramètres_2026!$B$22 -> 0
A38: Dividendes nets reçus | B38: =B35-B36-B37 -> 0
A40: 6. SYNTHÈSE COMPLÈTE
A41: IS payé par société | B41: =B30 -> 0
A42: PFU + PS sur dividendes distribués | B42: =B36+B37 -> 0
A43: Charge fiscale totale | B43: =B41+B42 -> 0
A44: Taux effectif sur loyers | B44: =IF(B5>0,B43/B5,0) -> 0
A45: Trésorerie capitalisée dans SCI | B45: =B31-B35 -> 0 | D45: Réinvestissable sans frottement fiscal supplémentaire
A47: 7. PLUS-VALUE À LA REVENTE (régime spécifique IS)
...

Sheet 10_Pinel_Denormandie
A1: DISPOSITIFS PINEL / DENORMANDIE / BAILLEUR PRIVÉ
A2: ⚠ ATTENTION : Pinel arrêté au 31/12/2024. Statut Bailleur Privé créé par LF 2026 (décrets en attente).
A4: ⚠ POINT CRITIQUE POUR LE MVP
A5: Pinel : DISPOSITIF FERMÉ aux nouvelles acquisitions depuis le 31/12/2024.
A6: Les investisseurs ENGAGÉS avant cette date continuent de bénéficier de la réduction d'impôt jusqu'à fin de l'engagement.
A7: Denormandie : prorogé jusqu'au 31/12/2027 (rénovation lourde dans centres-villes éligibles).
A8: Bailleur Privé (LF 2026) : nouveau dispositif d'amortissement accéléré, en remplacement partiel du Pinel.
A9: → POUR LE MVP : ne PAS proposer Pinel comme option pour primo-investisseur en 2026.
A10: → Dans le simulateur : afficher Pinel uniquement en 'mode rétrospectif' pour ceux qui sont déjà engagés.
A12: 1. PINEL (rappel pour propriétaires déjà engagés)
A13: Engagement location | B13: Réduction totale | C13: Taux annuel
A14: 6 ans | B14: 0.09 | C14: 0.015
A15: 9 ans | B15: 0.12 | C15: 0.0133
A16: 12 ans | B16: 0.14 | C16: 0.0117
A18: Plafond investissement annuel | B18: 300000 | D18: Art. 199 novovicies CGI
A19: Plafond prix au m² | B19: 5500 | D19: Plafond toutes zones
A20: Plafond loyer/m² (variable selon zone) | B20: 18.25 | D20: Zone A bis - 2024
A21: Réduction max sur 12 ans | B21: =MIN(B18,300000)*0.14 -> 42000 | D21: Plafonnée niches fiscales 10 000€/an
A23: 2. DENORMANDIE (actif jusqu'au 31/12/2027)
A24: Cible : rénovation de logements anciens dans centres-villes en perte de vitalité
A25: Conditions : 25% du prix dédiés à des travaux d'amélioration
A26: Liste des communes éligibles : 245 villes 'Action Cœur de Ville' + 222 villes 'ORT'
A27: Mêmes taux et engagements que Pinel (9-12-14% sur 6/9/12 ans)
A28: Plafonds : 300 000 €, 5 500 €/m², plafonds de loyers et de ressources locataires
A29: → Actif - peut être inclus dans le simulateur MVP avec module 'Denormandie'
A31: 3. STATUT DU BAILLEUR PRIVÉ (LF 2026 - en attente décrets)
A32: Nouveau dispositif d'amortissement créé par la LF 2026 pour relancer l'investissement locatif
A33: Cible : logements collectifs neufs en zone tendue OU anciens avec rénovation significative
A34: Mécanisme : amortissement déductible des revenus fonciers (similaire au régime BIC mais en location nue)
A35: Conditions précises : décrets d'application en attente fin 2026
... A37: → Veille réglementaire : suivre le BOFiP-Impôts pour mise à jour

Sheet 11_Plus_values
A1: PLUS-VALUES IMMOBILIÈRES - COMPARAISON PAR RÉGIME
A2: Calculs pour une cession à l'horizon défini dans Inputs simulation
A4: 1. HYPOTHÈSES DE CESSION
A5: Prix d'acquisition | B5: =02_Inputs_simulation!$B$10 -> 250000
A6: Frais d'acquisition (forfait 7,5% ou réels) | B6: =02_Inputs_simulation!$B$10*0.075 -> 18750 | D6: Forfait à défaut de justificatifs
A7: Travaux (forfait 15% si >5 ans) | B7: =02_Inputs_simulation!$B$10*0.15 -> 37500 | D7: Forfait OU réels avec factures
A8: Prix d'acquisition retenu | B8: =B5+B6+B7 -> 306250
A9: Durée de détention | B9: =02_Inputs_simulation!$B$36 -> 0.02
A10: Prix de cession estimé | B10: =02_Inputs_simulation!$B$10*POWER(1+02_Inputs_simulation!B37,B9) -> 250000 | D10: Prix d'achat capitalisé au taux d'appréciation
A11: Plus-value brute | B11: =B10-B8 -> -56250
A13: 2. RÉGIME DES PARTICULIERS (nom propre, SCI IR)
A14: Abattement IR par an (6e à 21e) | B14: 0.06
A15: Abattement IR 22e année | B15: 0.04
A16: Abattement PS par an (6e à 21e) | B16: 0.0165
A17: Abattement PS 22e année | B17: 0.016
A18: Abattement PS par an (23e à 30e) | B18: 0.09
A20: % abattement IR cumulé | B20: =IF(B9<6,0,IF(B9<22,(B9-5)*B14,IF(B9<23,16*B14+B15,1))) -> 0 | D20: 0% si <6 ans, max 100% à 22 ans
A21: % abattement PS cumulé | B21: =IF(B9<6,0,IF(B9<22,(B9-5)*B16,IF(B9<23,16*B16+B17,IF(B9<31,16*B16+B17+(B9-22)*B18,1)))) -> 0 | D21: 0% si <6 ans, max 100% à 30 ans
A22: Plus-value après abattement IR | B22: =B11*(1-B20) -> -56250
A23: Plus-value après abattement PS | B23: =B11*(1-B21) -> -56250
A24: IR à 19% | B24: =B22*0.19 -> -10687.5
A25: PS à 17,2% | B25: =B23*0.172 -> -9675
A26: Surtaxe (>50k€) | B26: =IF(B22>50000,B22*0.02,0) -> 0 | D26: Approximation - barème progressif 2-6%
A27: TOTAL imposition PV (régime particulier) | B27: =B24+B25+B26 -> -20362.5
A28: Net après PV | B28: =B11-B27 -> -35887.5
A30: 3. RÉGIME LMNP - APRÈS RÉFORME LF 2025
A31: Amortissements pratiqués (estimés) | B31: =(06_Réel_BIC_LMNP!B31)*B9 -> -167.33235 | D31: Cumul amortissement bâti+mobilier sur durée détention - signe inversé
A32: PV recalculée (réintégration amort.) | B32: =B11+ABS(B31) -> -56082.668 | D32: PV imposable = Prix vente - (Prix achat - Amort.)
A33: Application abattements particuliers | B33: =B32*(1-B20) -> -56082.668 | D33: Régime PV particuliers s'applique malgré réintégration
A34: IR à 19% | B34: =B33*0.19 -> -10655.707
A35: PS à 17,2% sur PV abattue PS | B35: =B32*(1-B21)*0.172 -> -9646.2188
A36: TOTAL imposition PV (LMNP) | B36: =B34+B35 -> -20301.926
A37: Surcoût LF 2025 vs ancien régime | B37: =B36-B27 -> 60.574311 | D37: Coût de la réforme
A39: 4. RÉGIME SCI IS
A40: Amortissements cumulés SCI IS | B40: =(09_SCI_IS!B20)*B9 -> -144.47521 | D40: Cumul amortissement bâti
A41: Valeur Nette Comptable (VNC) | B41: =B5-ABS(B40) -> 249855.52 | D41: VNC = Prix achat - amortissements
A42: Plus-value imposable IS | B42: =B10-B41 -> 144.47521 | D42: Pas d'abattement durée détention en IS
A43: IS sur PV (15% jusqu'à 42 500€) | B43: =MIN(MAX(0,B42),42500)*0.15 -> 21.671281
A44: IS taux normal 25% | B44: =MAX(0,B42-42500)*0.25 -> 0
A45: IS total | B45: =B43+B44 -> 21.671281
...

Sheet 12_Comparateur
A1: COMPARATEUR MULTI-RÉGIMES
A2: Vue synthétique côte-à-côte - C'EST L'ÉCRAN DE RÉSULTAT du simulateur utilisateur
A4: Indicateur | B4: Micro-foncier (loc. nue) | C4: Réel foncier (loc. nue) | D4: Micro-BIC LMNP | E4: Réel LMNP | F4: SCI IR | G4: SCI IS
A5: Loyer brut annuel | B5: =02_Inputs_simulation!$B$25 -> 13200 | C5: =02_Inputs_simulation!$B$25 -> 13200 | D5: =02_Inputs_simulation!$B$25 -> 13200 | E5: =02_Inputs_simulation!$B$25 -> 13200 | F5: =02_Inputs_simulation!$B$25 -> 13200 | G5: =02_Inputs_simulation!$B$25 -> 13200
A6: Recettes nettes (après vacance) | B6: =03_Micro_foncier!B7 -> 12672 | C6: =04_Réel_foncier!B7 -> 12672 | D6: =05_Micro_BIC_LMNP!B7 -> 12672 | E6: =06_Réel_BIC_LMNP!B7 -> 12672 | F6: =08_SCI_IR!B12+08_SCI_IR!B13 -> 12672 | G6: =09_SCI_IS!B5+09_SCI_IS!B6 -> 12672
A7: Charges déductibles | B7: =03_Micro_foncier!B9 -> -3801.6 | C7: =04_Réel_foncier!B17 -> -13809 | D7: =05_Micro_BIC_LMNP!B12 -> -6336 | E7: =06_Réel_BIC_LMNP!B18 -> -14689 | F7: =SUM(08_SCI_IR!B14:B16) -> -14389 | G7: =SUM(09_SCI_IS!B7:B9) -> -15289
A8: Amortissements | B8: - | C8: - | D8: - | E8: =06_Réel_BIC_LMNP!B31 -> -8366.6176 | F8: - | G8: =09_SCI_IS!B20 -> -7223.7604
A9: Bénéfice imposable | B9: =03_Micro_foncier!B10 -> 8870.4 | C9: =04_Réel_foncier!B26 -> 0 | D9: =05_Micro_BIC_LMNP!B13 -> 6336 | E9: =06_Réel_BIC_LMNP!B39 -> 0 | F9: =08_SCI_IR!B21 -> -1717 | G9: =09_SCI_IS!B24 -> 0
A10: IR / IS | B10: =03_Micro_foncier!B14 -> 2661.12 | C10: =04_Réel_foncier!B30 -> 0 | D10: =05_Micro_BIC_LMNP!B17 -> 1900.8 | E10: =06_Réel_BIC_LMNP!B43 -> 0 | F10: =08_SCI_IR!B25 -> 0 | G10: =09_SCI_IS!B30 -> 0
A11: Prélèvements sociaux | B11: =03_Micro_foncier!B18 -> 1525.7088 | C11: =04_Réel_foncier!B32 -> 0 | D11: =05_Micro_BIC_LMNP!B21 -> 1178.496 | E11: =06_Réel_BIC_LMNP!B44 -> 0 | F11: =08_SCI_IR!B26 -> 0 | G11: =09_SCI_IS!B37 -> 0
A12: CHARGE FISCALE TOTALE | B12: =03_Micro_foncier!B21 -> 4186.8288 | C12: =04_Réel_foncier!B36 -> -3210 | D12: =05_Micro_BIC_LMNP!B24 -> 3079.296 | E12: =06_Réel_BIC_LMNP!B45 -> 0 | F12: =08_SCI_IR!B28 -> -515.1 | G12: =09_SCI_IS!B43 -> 0
A13: Taux effectif sur loyers | B13: =03_Micro_foncier!B22 -> 0.3304 | C13: =04_Réel_foncier!B37 -> -0.25331439 | D13: =05_Micro_BIC_LMNP!B25 -> 0.243 | E13: =06_Réel_BIC_LMNP!B46 -> 0 | F13: =IF(08_SCI_IR!B12>0,08_SCI_IR!B28/08_SCI_IR!B12,0) -> -0.039022727 | G13: =09_SCI_IS!B44 -> 0
A15: RÉGIME LE PLUS FAVORABLE (charge fiscale min) | B15: =INDEX($B$4:$G$4,MATCH(MIN(B12:G12),B12:G12,0)) -> Réel foncier (loc. nue)
A17: MATRICE DE DÉCISION RAPIDE
A18: Critère | B18: Recommandation
A19: Bien sans emprunt + charges < 30% loyers | B19: Micro-foncier (location nue)
A20: Emprunt en cours + charges importantes (location nue) | B20: Réel foncier
A21: Gros travaux > 10 700 € à imputer | B21: Réel foncier (déficit foncier)
A22: Meublé sans emprunt, recettes < 77 700 € | B22: Micro-BIC LMNP (50%)
A23: Meublé avec emprunt, horizon long | B23: Réel LMNP (amortissement)
A24: Recettes meublé > 23 000 € + > revenus pro | B24: LMP (vérifier basculement)
A25: Patrimoine familial, transmission, location nue | B25: SCI à l'IR
A26: Capitalisation long terme, location meublée en société | B26: SCI à l'IS
A27: Investisseur LMNP existant qui restructure | B27: Étude SCI IS au cas par cas
A28: Primo-investisseur en RP non-investi | B28: Souvent : nom propre + LMNP réel

Sheet 13_Hypothèses_calcul
A1: HYPOTHÈSES, CONVENTIONS & SOURCES LÉGALES
A2: Document à fournir à l'expert-comptable pour validation avant intégration produit
A4: 1. APPROXIMATIONS APPLIQUÉES (à challenger avec un EC)
A5: Approximation | B5: Valeur retenue | C5: Précision réelle
A6: Calcul IR via TMI seule | B6: TMI × revenu imposable | C6: Le calcul exact passe par le barème complet par tranches + quotient familial + plafonnement
A7: Intérêts emprunt en année 1 | B7: Capital × taux | C7: En réalité dégressif - utiliser un tableau d'amortissement précis
A8: Amortissement linéaire pondéré bâti | B8: Décomposition 5 composants | C8: Standard comptable - l'EC peut affiner selon DTU
A9: Surtaxe PV simplifiée | B9: 2% si PV > 50 000 € | C9: En réalité barème progressif 2% à 6% selon montant
A10: Cotisations sociales LMP | B10: 30% | C10: En réalité 30-45% selon revenu - calcul SSI complexe
A11: Plafond niches fiscales | B11: Non modélisé | C11: Plafond global 10 000 €/an à intégrer (Pinel, etc.)
A12: CFE pour LMNP réel | B12: 300 €/an | C12: Variable selon commune (200-1500 €/an)
A13: Frais de gestion forfait foncier | B13: 20 €/local | C13: Art. 31-I-1°-c CGI - exact
A14: Vacance locative | B14: % des loyers | C14: Dans la réalité, non linéaire - conditionne la qualité du bien
A17: 2. SOURCES LÉGALES PRINCIPALES
A18: Texte | B18: Référence | C18: Sujet
A19: Loi de finances 2026 | B19: Loi n° 2026-103 du 19 février 2026 | C19: Barème IR 2026 (revalorisation +0,9%), CDHR, statut Bailleur Privé
A20: LFSS 2026 | B20: Art. 12 - hausse CSG 1,4 pt | C20: PS LMNP 17,2% → 18,6% (rétroactif rev. 2025), exclusion fonciers nus
A21: Loi Le Meur | B21: Loi n° 2024-1039 du 19/11/2024 | C21: Réforme micro-BIC meublés tourisme (15k€/30%)
A22: LF 2025 | B22: Art. 84 LF 2025 | C22: Réintégration amortissements LMNP dans plus-value
A23: CGI art. 32 | B23: Code général impôts | C23: Micro-foncier - location nue
A24: CGI art. 50-0 | B24: Code général impôts | C24: Micro-BIC - location meublée
A25: CGI art. 155 IV | B25: Code général impôts | C25: Statut LMP / LMNP - seuil 23 000 €
A26: CGI art. 156 I-3° | B26: Code général impôts | C26: Déficit foncier - plafond 10 700 €
A27: CGI art. 219 I | B27: Code général impôts | C27: IS - taux réduit 15% / normal 25%
A28: CGI art. 239 | B28: Code général impôts | C28: Option IS - irrévocabilité après 5 ans
A29: CGI art. 150 U | B29: Code général impôts | C29: Plus-values immobilières particuliers
A30: BOFiP-Impôts | B30: BOI-BIC-CHAMP-40 | C30: Doctrine administrative location meublée
A33: 3. POINTS D'ATTENTION POUR LE PRODUIT
A34: 1. La fiscalité immobilière évolue chaque année (LF + LFSS) - prévoir mise à jour annuelle Q1
A35: 2. Le statut Bailleur Privé (LF 2026) sera disponible courant 2026 après publication des décrets
A36: 3. La CDHR (Contribution Différentielle Hauts Revenus) plancher 20% concerne les RFR > 250k€/500k€
A37: 4. La loi 'climat-résilience' interdit la location de biens classés G au DPE depuis 01/01/2025
A38: 5. Pinel : ne plus l'inclure dans le simulateur pour nouveaux investisseurs (sauf engagements pris avant 31/12/2024)
A39: 6. Les calculs ne couvrent PAS : démembrement, holding patrimoniale, OBO, dispositif Cosse, monuments historiques, Malraux
A40: 7. Cas multi-biens : le calcul change (cumul recettes pour seuils LMP/LMNP, mutualisation déficits, etc.)
A41: 8. Cas indivision : régime particulier proche de la SCI IR mais avec des règles spécifiques
A42: 9. Le simulateur doit clairement distinguer 'recettes' (encaissé) et 'résultat fiscal' (imposable)
A43: 10. Prévoir un disclaimer légal : 'outil d'aide à la décision, ne se substitue pas à un conseil personnalisé'
